错误至少被分为两种: 语法错误和异常.

## 语法错误
语法错误又称解析错误:
解析器会重复存在错误的行兵显示一个指向该行中检测到错误的词元的 "箭头".
文件名和行号也会被打印出来以便你再输入是来自脚本时可以知道要去哪里查找问题.

## 异常(Error)
即便语句和表达式都使用了正确的语法, 执行时仍可能触发错误.
执行时检测到的错误称为 **异常**, 异常不一定导致严重的后果, 大多数异常不会被程序处理, 而是显示错误信息.

错误信息的最后一行说明程序遇到了什么类型的错误.
异常有不同的类型, 而类型名称会作为错误信息的一部分打印出来.
作为异常类型打印的字符串是发生的内置异常的名称. 所有内置异常都是如此, 但对于用户定义的异常则不一定. 
标准的异常类型是内置的标识符(不是保留关键字).
#### 异常的处理
通过编写程序来处理选定的异常.
```python
while True:
	try:
		x = int(input("Please enter a number: "))
	except ValueError:
		print("Oops! That was no valid number. Try again...")
```
此例中会要求用户一直输入内容, 知道输入有效的整数, 但允许用户终端程序(Ctrl-c). 用户终端程序会触发 KeyboardInterrupt 异常.
try语句的工作原理:
- 执行try子句;
- 如果没有触发异常, 则跳过except子句, try语句执行完毕.
- 如果执行try子句时发生了异常,则跳过该子句中剩下的部分. 如果异常的类型与except关键字后指定的异常相匹配, 则执行 except子句, 然后跳到try/except代码块之后继续执行.
- 如果发生的异常与except子句中指定的异常不匹配, 则它会被传递到外层的try语句中; 如果没有找到处理器, 则它是一个未处理异常且执行将停止并输出一条错误信息.
except子句可以用圆括号的元组来指定多个异常:
```python
except (RuntimeError, TypeError, NameError):
	pass
```
一个except子句中的类匹配的异常将是该类本身的实例或其所派生的类的实例. (列出派生类的except子句不会匹配其基类的实例):
```python
class B(Exception):
	pass

class C(B):
	pass

class D(C):
	pass

for cls in [B, C, D]:
	try:
		raise cls()
	except D:
		print("D")
	except C:
		print("C")
	except B:
		print("B")
```
注: 如果把except B放在最前面, 则输出的结果将是 B, B, B, 默认会触发第一个匹配的except子句.
**发生异常时, 它可能具有关联值, 即异常参数.** 是否需要参数, 以及参数的类型取决于异常的类型.
except子句可能会在异常名称后面指定一个变量. 这个变量将被绑到异常实例, 该实例通常会有一个存储参数的 args 属性. 为方便, 内置异常类型定义了 \_\_str\_\_()来打印所有参数而不必显式地访问 .args.
```python
try:
	raise Exception('spam', 'eggs')
except Exception as inst:
	print(type(inst))
	print(inst.args)
	print(inst)

	x, y = inst.args
	print('x = ', x)
	print('y = ', y)
```
未处理异常的 \_\_str\_\_() 输出会被打印为该异常消息的最后部分(detail).

BaseException是所有异常的共同基类, 它的一个子类, Exception, 是所有非致命异常的基类.
不是Exception的子类的异常通常不被处理, 因为它们被用来指示程序应该终止. 它们包括由sys.exit()引发的SystemExit, 以及当用户希望终端程序时引发的KeyboardInterrupt.
Exception可以被用作通配符, 捕获几乎一切. 但尽可能具体说明我们打算处理的异常类型, 并允许任意以外的异常传播下去.

处理Exception最常见的模式是打印或记录异常, 然后重新提出(允许调度者也处理异常):
```python
import sys
try:
	f = open('myfile.txt')
	s = f.readline()
	i = int(s.strip())
except OSError as err:
	print("OS error:", err)
except ValueError:
	print("Could not convert data to an integer.")
except Exception as err:
	print(f"Unexpected {err=}, {type(err)=}")
	raise
```
try...except 语句具有可选的 else子句.该子句如果存在, 必须放在所有except子句之后.
适用于try子句没有引发异常但又必须要执行的代码:
```python
for arg in sys.argv[1:]:
	try:
		f = open(arg, 'r')
	except OSError:
		print("cannot open", arg)
	else:
		print(arg, 'has', len(f.readlines()), 'lines')
		f.close()
```
使用else子句比向try子句添加额外的代码要好, 可以避免意外捕获非try...except语句保护的代码触发的异常.
异常处理程序不仅会处理在try子句中立刻发生的异常, 还会处理在try子句中调用的函数:
```python
def this_fails()
	x = 1/0

try:
	this_fails()
except ZeroDivisionError as err:
	print("Handling run-time error:", err)
```

#### 触发异常
raise语句支持强制触发指定异常:
```python
raise NameError("HiTherr")
```
raise 唯一的参数就是要触发的异常. 必须是异常实例或异常类.
如果传递的是异常类, 将通过调用没有参数的构造函数来隐式实例化:
```python
rasie ValueError  #shorthand for 'raise ValueError()'
```
如果只想判断是否触发了异常, 并不打算处理该异常, 可以使用简单的raise语句重新触发异常:
```python
try:
	raise NameError('HiThere')
except NameError:
	print('An exception flew by!')
	raise
```

#### 异常链
如果一个未处理的异常发生在except部分内, 它将会有被处理的异常附加到它上面, 并包含在错误信息中:
```python
try:
	open('database.sqlite')
except OSError:
	raise RuntimeError("unable to handle error")
```
为表明一个异常是另一个异常的直接后果, raise语句允许一个可选的from子句:
```python
raise RuntimeError from exc
```
在转换异常时, 这种方式很有用:
```python
def func():
	raise ConnectionError

try:
	func()
except ConnectionError as exc:
	raise RuntimeError('Failed to open database') from exc
```
它还允许使用 from None表达禁用自动异常链:
```python
try:
	open('database.sqlite')
except OSError:
	raise RuntimeError from None
```

#### 用户自定义异常
程序可以通过创建新的异常类命名自己的异常, 不论是直接还是间接的方式, 异常都应从Exception类派生.
异常类可以被定义成能做其他类所能做的任何事, 但通常应当保持简单, 它往往只提供一些属性, 允许相应的异常处理程序提取有关错误的信息.
大多数异常命名都以 "Error"结尾.

#### 定义清理操作
try 语句还有一个可选子句, 用于定义在所有情况下都必须要执行的清理操作:
```python
try:
	raise KeyboardInterrupt
finally:
	print('Goodbye, world!')
```
如果存在finally子句, 则finally子句是try语句结束前执行的最后一项任务. 不论try语句是否触发异常, 都会执行finally子句.
几种复杂的触发异常场景:
- 如果执行try子句期间触发了某个异常, 则某个except子句应处理该异常, 如果该异常没有except子句处理, 在finalyy子句执行后会被重新触发;
- except或else子句执行期间也会触发异常. 同样, 该异常会在finally子句执行之后被重新触发;
- 如果finally子句中包含break, continue或return等语句, 异常将不会被重新引发;
- 如果执行try语句时遇到break,continue或return语句, 则finally子句在执行break, continue或return语句之前执行;
- 如果finally子句中包含return语句, 则返回值来自finally子句的某个return语句的返回值, 而不是来自try子句的return语句的返回值.
```python
def bool_return():
	try:
		return True
	finally:
		return False

bool_return()   #返回False
```
稍微复杂的例子:
```python
def divide(x, y):
	try:
		result = x / y
	except ZeroDivisionError:
		print('division by zero!')
	else:
		print("result is ", result)
	finally:
		print("executing finally clause")

divide(2, 1)
#result is 2.0
#executing finally clause
divide(2, 0)
#division by zero!
#executing finally clause
divide("2", "1")
#executing finally clause
#报错信息, TypeError
```
任何情况下都会执行finally子句.
except子句不处理两个字符串相除触发的TypeError, 因此会在finally子句执行后被重新触发.
在实际应用程序中, finally子句对于释放外部资源非常有用, 无论是否成功使用资源.

#### 预定义的清理操作
某些对象定义了不需要该对象时要执行的标准清理操作. 无论使用该对象的操作是否成功, 都会执行清理操作:
```python
for line in open("myfile.txt"):
	print(line, end="")
```
这段代码的问题在于, 执行完代码后, 文件在一段不确定的时间内处于打开状态.
对于应用程序来说, 可能会出现问题, with语句支持以及时, 正确的清理方式使用文件对象:
```python
with open("myfile.txt") as f:
	for line in f:
		print(line, end="")
```
语句执行完毕后, 及时在处理行时遇到问题, 都会关闭文件f.

#### 引发和处理多个不相关的异常
在有些情况下, 有必要报告几个已经发生的异常.
这通常在并发框架中当几个任务并行失败时的情况, 也有其他的用例, 有时需要是继续执行并收集多个错误而不是引发第一个异常.
内置的ExceptionGroup打包了一个异常实例的列表, 这样它们就可以一起被引发.
它本身就是一个异常, 因此它可以像其他异常一样被捕获.
```python
def f():
	excs = [OSError('error 1'), SystemError('error 2')]
	raise ExceptionGroup('there were problems', excs)

f()

try:
	f()
except Exception as e:
	print(f'caught {type(e)}: e')
#caught <class 'ExceptionGroup'>: e
```
通常使用except\*代替except, 我们可以有选择地只处理组中符合某种类型的异常.
```python
def f():
	raise ExceptionGroup(
		"group1", [OSError(1), SystemError(2),
			ExceptionGroup(
				"group2", 
					[OSError(3), RecursionError(4)]
			)]
	
	)

try:
	f()
except* OSError as e:
	print("There were OSErrors")
except* SystemError as e:
	print("There were SystemErrors")
```
嵌套异常组, 每个except\*子句都从组中提取某种类型的异常, 而让所有其他的异常传播到其他子句, 并最终被重新引发.
注, 嵌套在一个异常组中的异常必须是实例, 而不是类型.
因为在实践中, 这些异常通常是那些已经被程序提出并捕获的异常:
```python
excs = []
for test in tests:
	try
		test.run()
	except Exception as e:
		excs.append(e)

if excs:
	raise ExceptionGroup("Test failures", excs)
```

#### 用注释细化异常情况
当一个异常被创建以引发时, 它通常被初始化为描述所发生错误的信息.
在有些情况下, 在异常被捕获后添加信息是很有用的. 为了这个目的, 异常有一个 add_note(note)方法接受一个字符串, 并将其添加到异常的注释列表.
标准的回溯在异常之后按照它们被添加的顺序呈现包括所有的注释:
```python
try:
	raise TypeError('bad type'):
except Exception as e:
	e.add_note('Add some information')
	e.add_note('Add some more information')
	raise

#Traceback (most recent call last):
#  File "<stdin>", line2, in <module>
#TypeError: bad type
#Add some information
#Add some more information
```
例如, 当把异常收集到一个异常组时, 我们可能想为各个错误添加上下文信息.
在下文中, 组中的每个异常都有一个说明, 指出这个错误是什么时候发生的:
```python
def f():
	raise OSError("operation failed")

excs = []
for i in range(3):
	try:
		f()
	except Exception as e:
		e.add_note(f"Happened in Interation {i+1}")
		excs.append(e)

raise ExceptionGroup("We have some problems", excs)
```
